Workbook

Sheet Order June 26
A1: Product Name | B1: Landing Cost | C1: MRP | D1: Price/unit | E1: Kumar Saurav | F1: Sandhya | G1: Vishal Sinha | H1: Anindya Padhy | I1: Sonali Chatterjee | J1: Digvijay | K1: Sonal Jaiswal | L1: Georgina | M1: Komal Jaiswal | N1: Rachana | O1: Saurav | P1: Anand vardhan Lal | Q1: Adarsh Bhaskar Kulkarni | R1: Advaita | S1: Tushar Anand | T1: Rishab Chowdhary | U1: Shalina | V1: Yash Agrawal | W1: Column 20 | X1: Total
A2: Mustard Oil - Organic | B2: ='June 26 Price List'!C2 -> 249.59 | C2: ='June 26 Price List'!D2 -> 440 | D2: ='June 26 Price List'!E2 -> 340 | E2: 0 | F2: 0 | G2: 0 | H2: 0 | I2: 2 | J2: 0 | K2: 1 | L2: 0 | M2: 2 | N2: 1 | O2: 0 | P2: 0 | Q2: 0 | R2: 0
A3: Mustard Oil - Regular | B3: ='June 26 Price List'!C3 -> 240.75 | C3: ='June 26 Price List'!D3 -> 310 | D3: ='June 26 Price List'!E3 -> 285 | E3: 1 | F3: 2 | G3: 2 | H3: 2 | J3: 2 | K3: 0 | L3: 0 | M3: 0 | N3: 0 | O3: 2 | P3: 2 | Q3: 0 | R3: 1
A4: Groundnut Oil - Organic | B4: ='June 26 Price List'!C4 -> 257.99 | C4: ='June 26 Price List'!D4 -> 469 | D4: ='June 26 Price List'!E4 -> 350 | E4: 0 | F4: 0 | G4: 0 | H4: 0 | I4: 1 | J4: 0 | K4: 1 | L4: 0 | M4: 0 | N4: 1 | O4: 0 | P4: 0 | Q4: 0 | R4: 0
A5: Groundnut Oil - Regular | B5: ='June 26 Price List'!C5 -> 278.21 | C5: ='June 26 Price List'!D5 -> 339 | D5: ='June 26 Price List'!E5 -> 325 | E5: 1 | F5: 1 | G5: 2 | H5: 1 | J5: 2 | K5: 0 | L5: 0 | M5: 0 | N5: 0 | O5: 1 | P5: 1 | Q5: 0 | R5: 1
A6: Sunflower Oil - Organic | B6: ='June 26 Price List'!C6 -> 262.79 | C6: ='June 26 Price List'!D6 -> 469 | D6: ='June 26 Price List'!E6 -> 350 | E6: 1 | F6: 1 | G6: 2 | H6: 1 | I6: 1 | J6: 1 | K6: 0 | L6: 2 | M6: 0 | N6: 1 | O6: 1 | P6: 1 | Q6: 2 | R6: 0
A7: Coconut Oil - Regular | B7: ='June 26 Price List'!C7 -> 60.99 | C7: ='June 26 Price List'!D7 -> 159 | D7: ='June 26 Price List'!E7 -> 109 | E7: 1 | F7: 5 | G7: 1 | H7: 1 | I7: 1 | J7: 5 | K7: 0 | L7: 5 | M7: 5 | N7: 5 | O7: 5 | P7: 1 | Q7: 0 | R7: 5
A8: Sesame Oil - Regular | B8: ='June 26 Price List'!C8 -> 42.8 | C8: ='June 26 Price List'!D8 -> 159 | D8: ='June 26 Price List'!E8 -> 109 | E8: 1 | F8: 5 | G8: 1 | H8: 1 | I8: 1 | J8: 5 | K8: 5 | L8: 0 | M8: 5 | N8: 0 | O8: 5 | P8: 1 | Q8: 0 | R8: 5
A9: A2 Ghee Gir Cow | B9: ='June 26 Price List'!C9 -> 1284.02 | C9: ='June 26 Price List'!D9 -> 2099 | D9: ='June 26 Price List'!E9 -> 1699 | E9: 1 | F9: 1 | G9: 1 | H9: 1 | I9: 1 | J9: 1 | K9: 1 | L9: 1 | M9: 1 | N9: 1 | O9: 1 | P9: 1 | Q9: 1 | R9: 1
A10: Chana Dal- Organic | B10: ='June 26 Price List'!C10 -> 96 | C10: ='June 26 Price List'!D10 -> 189 | D10: ='June 26 Price List'!E10 -> 150 | E10: 0 | F10: 1 | G10: 1 | H10: 1 | I10: 1 | J10: 1 | K10: 1 | L10: 0.5 | M10: 0.5 | N10: 1 | O10: 1 | P10: 1 | Q10: 0 | R10: 0.5
A11: Moong Dal - Organic | B11: ='June 26 Price List'!C11 -> 136.79 | C11: ='June 26 Price List'!D11 -> 219 | D11: ='June 26 Price List'!E11 -> 180 | E11: 0 | F11: 0 | G11: 1 | H11: 1 | I11: 1 | J11: 2 | K11: 1 | L11: 1 | M11: 1 | N11: 0 | O11: 1 | P11: 1 | Q11: 0 | R11: 1
A12: Tuar Dal - Organic | B12: ='June 26 Price List'!C12 -> 166.79 | C12: ='June 26 Price List'!D12 -> 239 | D12: ='June 26 Price List'!E12 -> 199 | E12: 0 | F12: 0 | G12: 1 | H12: 1 | I12: 1 | J12: 0 | K12: 1 | L12: 0.5 | M12: 1 | N12: 1 | O12: 1 | P12: 1 | Q12: 2 | R12: 1
A13: Masoor Dal- Organic | B13: ='June 26 Price List'!C13 -> 116.39 | C13: ='June 26 Price List'!D13 -> 219 | D13: ='June 26 Price List'!E13 -> 180 | E13: 2 | F13: 2 | G13: 1 | H13: 0 | I13: 1 | J13: 1 | K13: 1 | L13: 1 | M13: 0.5 | N13: 2 | O13: 1 | P13: 1 | Q13: 0 | R13: 0
A14: Basmati Rice- Organic | B14: ='June 26 Price List'!C14 -> 143.99 | C14: ='June 26 Price List'!D14 -> 210 | D14: ='June 26 Price List'!E14 -> 210 | E14: 0 | F14: 0 | G14: 0.5 | H14: 0 | I14: 0.5 | J14: 0 | K14: 0.5 | L14: 0.5 | M14: 0 | N14: 0.5 | O14: 0.5 | P14: 0.5 | Q14: 0 | R14: 0.5
A15: Sona Masoori Rice - Organic | B15: ='June 26 Price List'!C15 -> 76.8 | C15: ='June 26 Price List'!D15 -> 139 | D15: ='June 26 Price List'!E15 -> 100 | E15: 0 | F15: 0 | G15: 2 | H15: 0 | I15: 2 | J15: 2 | K15: 0 | L15: 0 | M15: 2 | N15: 2 | O15: 2 | P15: 2 | Q15: 0 | R15: 1
A16: JeeraPhool Rice - Organic | B16: ='June 26 Price List'!C16 -> 88.23 | C16: ='June 26 Price List'!D16 -> 259 | D16: ='June 26 Price List'!E16 -> 240 | E16: 0 | F16: 0 | G16: 0 | H16: 1 | I16: 1 | J16: 1 | K16: 1 | L16: 0 | M16: 1 | N16: 0 | O16: 1 | P16: 1 | Q16: 2 | R16: 1
A17: Khapli Aata - Regular | B17: ='June 26 Price List'!C17 -> 101.65 | C17: ='June 26 Price List'!D17 -> 159 | D17: ='June 26 Price List'!E17 -> 149 | E17: 2 | F17: 5 | G17: 2 | H17: 2 | I17: 2 | J17: 1 | K17: 2 | L17: 2 | M17: 2 | N17: 2 | O17: 2 | P17: 2 | Q17: 2 | R17: 2
... A20: Coconut Husk | B20: ='June 26 Price List'!C20 -> 31 | C20: ='June 26 Price List'!D20 -> 0 | D20: ='June 26 Price List'!E20 -> 0 | E20: 1 | F20: 1 | G20: 1 | H20: 1 | I20: 1 | J20: 1 | K20: 1 | L20: 1 | M20: 1 | N20: 1 | O20: 1 | P20: 1 | Q20: 1 | R20: 1
A21: Total | E21: =$D$2*E2+$D$3*E3+$D$4*E4+$D$5*E5+$D$6*E6+$D$7*E7+$D$8*E8+$D$9*E9+$D$10*E10+$D$11*E11+$D$12*E12+$D$13*E13+$D$14*E14+$D$15*E15+$D$16*E16+$D$17*E17+$D$18*E18+$D$19*E19+$D$20*E20 -> 4035 | F21: =$D$2*F2+$D$3*F3+$D$4*F4+$D$5*F5+$D$6*F6+$D$7*F7+$D$8*F8+$D$9*F9+$D$10*F10+$D$11*F11+$D$12*F12+$D$13*F13+$D$14*F14+$D$15*F15+$D$16*F16+$D$17*F17+$D$18*F18+$D$19*F19+$D$20*F20 -> 5789 | G21: =$D$2*G2+$D$3*G3+$D$4*G4+$D$5*G5+$D$6*G6+$D$7*G7+$D$8*G8+$D$9*G9+$D$10*G10+$D$11*G11+$D$12*G12+$D$13*G13+$D$14*G14+$D$15*G15+$D$16*G16+$D$17*G17+$D$18*G18+$D$19*G19+$D$20*G20 -> 5649 | H21: =$D$2*H2+$D$3*H3+$D$4*H4+$D$5*H5+$D$6*H6+$D$7*H7+$D$8*H8+$D$9*H9+$D$10*H10+$D$11*H11+$D$12*H12+$D$13*H13+$D$14*H14+$D$15*H15+$D$16*H16+$D$17*H17+$D$18*H18+$D$19*H19+$D$20*H20 -> 4729 | I21: =$D$2*I2+$D$3*I3+$D$4*I4+$D$5*I5+$D$6*I6+$D$7*I7+$D$8*I8+$D$9*I9+$D$10*I10+$D$11*I11+$D$12*I12+$D$13*I13+$D$14*I14+$D$15*I15+$D$16*I16+$D$17*I17+$D$18*I18+$D$19*I19+$D$20*I20 -> 5349 | J21: =$D$2*J2+$D$3*J3+$D$4*J4+$D$5*J5+$D$6*J6+$D$7*J7+$D$8*J8+$D$9*J9+$D$10*J10+$D$11*J11+$D$12*J12+$D$13*J13+$D$14*J14+$D$15*J15+$D$16*J16+$D$17*J17+$D$18*J18+$D$19*J19+$D$20*J20 -> 6138 | K21: =$D$2*K2+$D$3*K3+$D$4*K4+$D$5*K5+$D$6*K6+$D$7*K7+$D$8*K8+$D$9*K9+$D$10*K10+$D$11*K11+$D$12*K12+$D$13*K13+$D$14*K14+$D$15*K15+$D$16*K16+$D$17*K17+$D$18*K18+$D$19*K19+$D$20*K20 -> 4786 | L21: =$D$2*L2+$D$3*L3+$D$4*L4+$D$5*L5+$D$6*L6+$D$7*L7+$D$8*L8+$D$9*L9+$D$10*L10+$D$11*L11+$D$12*L12+$D$13*L13+$D$14*L14+$D$15*L15+$D$16*L16+$D$17*L17+$D$18*L18+$D$19*L19+$D$20*L20 -> 4381.5 | ... W21: =$D$2*W2+$D$3*W3+$D$4*W4+$D$5*W5+$D$6*W6+$D$7*W7+$D$8*W8+$D$9*W9+$D$10*W10+$D$11*W11+$D$12*W12+$D$13*W13+$D$14*W14+$D$15*W15+$D$16*W16+$D$17*W17+$D$18*W18+$D$19*W19+$D$20*W20 -> 0 | X21: =SUM(D21:W21) -> 71424.5
A22: Discount | E22: =($C$2*E2+$C$3*E3+$C$4*E4+$C$5*E5+$C$6*E6+$C$7*E7+$C$8*E8+$C$9*E9+$C$10*E10+$C$11*E11+$C$12*E12+$C$13*E13+$C$14*E14+$C$15*E15+$C$16*E16+$C$17*E17+$C$18*E18+$C$19*E19+$C$20*E20)-E21 -> 854 | F22: =($C$2*F2+$C$3*F3+$C$4*F4+$C$5*F5+$C$6*F6+$C$7*F7+$C$8*F8+$C$9*F9+$C$10*F10+$C$11*F11+$C$12*F12+$C$13*F13+$C$14*F14+$C$15*F15+$C$16*F16+$C$17*F17+$C$18*F18+$C$19*F19+$C$20*F20)-F21 -> 1348 | G22: =($C$2*G2+$C$3*G3+$C$4*G4+$C$5*G5+$C$6*G6+$C$7*G7+$C$8*G8+$C$9*G9+$C$10*G10+$C$11*G11+$C$12*G12+$C$13*G13+$C$14*G14+$C$15*G15+$C$16*G16+$C$17*G17+$C$18*G18+$C$19*G19+$C$20*G20)-G21 -> 1169 | H22: =($C$2*H2+$C$3*H3+$C$4*H4+$C$5*H5+$C$6*H6+$C$7*H7+$C$8*H8+$C$9*H9+$C$10*H10+$C$11*H11+$C$12*H12+$C$13*H13+$C$14*H14+$C$15*H15+$C$16*H16+$C$17*H17+$C$18*H18+$C$19*H19+$C$20*H20)-H21 -> 938 | I22: =($C$2*I2+$C$3*I3+$C$4*I4+$C$5*I5+$C$6*I6+$C$7*I7+$C$8*I8+$C$9*I9+$C$10*I10+$C$11*I11+$C$12*I12+$C$13*I13+$C$14*I14+$C$15*I15+$C$16*I16+$C$17*I17+$C$18*I18+$C$19*I19+$C$20*I20)-I21 -> 1310 | J22: =($C$2*J2+$C$3*J3+$C$4*J4+$C$5*J5+$C$6*J6+$C$7*J7+$C$8*J8+$C$9*J9+$C$10*J10+$C$11*J11+$C$12*J12+$C$13*J13+$C$14*J14+$C$15*J15+$C$16*J16+$C$17*J17+$C$18*J18+$C$19*J19+$C$20*J20)-J21 -> 1458 | K22: =($C$2*K2+$C$3*K3+$C$4*K4+$C$5*K5+$C$6*K6+$C$7*K7+$C$8*K8+$C$9*K9+$C$10*K10+$C$11*K11+$C$12*K12+$C$13*K13+$C$14*K14+$C$15*K15+$C$16*K16+$C$17*K17+$C$18*K18+$C$19*K19+$C$20*K20)-K21 -> 1163 | L22: =($C$2*L2+$C$3*L3+$C$4*L4+$C$5*L5+$C$6*L6+$C$7*L7+$C$8*L8+$C$9*L9+$C$10*L10+$C$11*L11+$C$12*L12+$C$13*L13+$C$14*L14+$C$15*L15+$C$16*L16+$C$17*L17+$C$18*L18+$C$19*L19+$C$20*L20)-L21 -> 1123.5 | ... W22: =($C$2*W2+$C$3*W3+$C$4*W4+$C$5*W5+$C$6*W6+$C$7*W7+$C$8*W8+$C$9*W9+$C$10*W10+$C$11*W11+$C$12*W12+$C$13*W13+$C$14*W14+$C$15*W15+$C$16*W16+$C$17*W17+$C$18*W18+$C$19*W19+$C$20*W20)-W21 -> 0 | X22: =SUM(D22:W22) -> 16686
A23: Discount % | E23: =E22*100/($C$2*E2+$C$3*E3+$C$4*E4+$C$5*E5+$C$6*E6+$C$7*E7+$C$8*E8+$C$9*E9+$C$10*E10+$C$11*E11+$C$12*E12+$C$13*E13+$C$14*E14+$C$15*E15+$C$16*E16+$C$17*E17+$C$18*E18+$C$19*E19+$C$20*E20) -> 17.467785 | F23: =F22*100/($C$2*F2+$C$3*F3+$C$4*F4+$C$5*F5+$C$6*F6+$C$7*F7+$C$8*F8+$C$9*F9+$C$10*F10+$C$11*F11+$C$12*F12+$C$13*F13+$C$14*F14+$C$15*F15+$C$16*F16+$C$17*F17+$C$18*F18+$C$19*F19+$C$20*F20) -> 18.887488 | G23: =G22*100/($C$2*G2+$C$3*G3+$C$4*G4+$C$5*G5+$C$6*G6+$C$7*G7+$C$8*G8+$C$9*G9+$C$10*G10+$C$11*G11+$C$12*G12+$C$13*G13+$C$14*G14+$C$15*G15+$C$16*G16+$C$17*G17+$C$18*G18+$C$19*G19+$C$20*G20) -> 17.145791 | H23: =H22*100/($C$2*H2+$C$3*H3+$C$4*H4+$C$5*H5+$C$6*H6+$C$7*H7+$C$8*H8+$C$9*H9+$C$10*H10+$C$11*H11+$C$12*H12+$C$13*H13+$C$14*H14+$C$15*H15+$C$16*H16+$C$17*H17+$C$18*H18+$C$19*H19+$C$20*H20) -> 16.551968 | I23: =I22*100/($C$2*I2+$C$3*I3+$C$4*I4+$C$5*I5+$C$6*I6+$C$7*I7+$C$8*I8+$C$9*I9+$C$10*I10+$C$11*I11+$C$12*I12+$C$13*I13+$C$14*I14+$C$15*I15+$C$16*I16+$C$17*I17+$C$18*I18+$C$19*I19+$C$20*I20) -> 19.672624 | J23: =J22*100/($C$2*J2+$C$3*J3+$C$4*J4+$C$5*J5+$C$6*J6+$C$7*J7+$C$8*J8+$C$9*J9+$C$10*J10+$C$11*J11+$C$12*J12+$C$13*J13+$C$14*J14+$C$15*J15+$C$16*J16+$C$17*J17+$C$18*J18+$C$19*J19+$C$20*J20) -> 19.194313 | K23: =K22*100/($C$2*K2+$C$3*K3+$C$4*K4+$C$5*K5+$C$6*K6+$C$7*K7+$C$8*K8+$C$9*K9+$C$10*K10+$C$11*K11+$C$12*K12+$C$13*K13+$C$14*K14+$C$15*K15+$C$16*K16+$C$17*K17+$C$18*K18+$C$19*K19+$C$20*K20) -> 19.549504 | L23: =L22*100/($C$2*L2+$C$3*L3+$C$4*L4+$C$5*L5+$C$6*L6+$C$7*L7+$C$8*L8+$C$9*L9+$C$10*L10+$C$11*L11+$C$12*L12+$C$13*L13+$C$14*L14+$C$15*L15+$C$16*L16+$C$17*L17+$C$18*L18+$C$19*L19+$C$20*L20) -> 20.408719 | ... W23: =W22*100/($C$2*W2+$C$3*W3+$C$4*W4+$C$5*W5+$C$6*W6+$C$7*W7+$C$8*W8+$C$9*W9+$C$10*W10+$C$11*W11+$C$12*W12+$C$13*W13+$C$14*W14+$C$15*W15+$C$16*W16+$C$17*W17+$C$18*W18+$C$19*W19+$C$20*W20) -> #DIV/0! | X23: =AVERAGE(E23:Q23) -> 18.841049
A24: Margin | E24: =E21-($B$2*E2+$B$3*E3+$B$4*E4+$B$5*E5+$B$6*E6+$B$7*E7+$B$8*E8+$B$9*E9+$B$10*E10+$B$11*E11+$B$12*E12+$B$13*E13+$B$14*E14+$B$15*E15+$B$16*E16+$B$17*E17+$B$18*E18+$B$19*E19+$B$20*E20) -> 1132.66 | F24: =F21-($B$2*F2+$B$3*F3+$B$4*F4+$B$5*F5+$B$6*F6+$B$7*F7+$B$8*F8+$B$9*F9+$B$10*F10+$B$11*F11+$B$12*F12+$B$13*F13+$B$14*F14+$B$15*F15+$B$16*F16+$B$17*F17+$B$18*F18+$B$19*F19+$B$20*F20) -> 1829.8 | G24: =G21-($B$2*G2+$B$3*G3+$B$4*G4+$B$5*G5+$B$6*G6+$B$7*G7+$B$8*G8+$B$9*G9+$B$10*G10+$B$11*G11+$B$12*G12+$B$13*G13+$B$14*G14+$B$15*G15+$B$16*G16+$B$17*G17+$B$18*G18+$B$19*G19+$B$20*G20) -> 1456.125 | H24: =H21-($B$2*H2+$B$3*H3+$B$4*H4+$B$5*H5+$B$6*H6+$B$7*H7+$B$8*H8+$B$9*H9+$B$10*H10+$B$11*H11+$B$12*H12+$B$13*H13+$B$14*H14+$B$15*H15+$B$16*H16+$B$17*H17+$B$18*H18+$B$19*H19+$B$20*H20) -> 1330.88 | I24: =I21-($B$2*I2+$B$3*I3+$B$4*I4+$B$5*I5+$B$6*I6+$B$7*I7+$B$8*I8+$B$9*I9+$B$10*I10+$B$11*I11+$B$12*I12+$B$13*I13+$B$14*I14+$B$15*I15+$B$16*I16+$B$17*I17+$B$18*I18+$B$19*I19+$B$20*I20) -> 1611.435 | J24: =J21-($B$2*J2+$B$3*J3+$B$4*J4+$B$5*J5+$B$6*J6+$B$7*J7+$B$8*J8+$B$9*J9+$B$10*J10+$B$11*J11+$B$12*J12+$B$13*J13+$B$14*J14+$B$15*J15+$B$16*J16+$B$17*J17+$B$18*J18+$B$19*J19+$B$20*J20) -> 1908.17 | K24: =K21-($B$2*K2+$B$3*K3+$B$4*K4+$B$5*K5+$B$6*K6+$B$7*K7+$B$8*K8+$B$9*K9+$B$10*K10+$B$11*K11+$B$12*K12+$B$13*K13+$B$14*K14+$B$15*K15+$B$16*K16+$B$17*K17+$B$18*K18+$B$19*K19+$B$20*K20) -> 1604.205 | L24: =L21-($B$2*L2+$B$3*L3+$B$4*L4+$B$5*L5+$B$6*L6+$B$7*L7+$B$8*L8+$B$9*L9+$B$10*L10+$B$11*L11+$B$12*L12+$B$13*L13+$B$14*L14+$B$15*L15+$B$16*L16+$B$17*L17+$B$18*L18+$B$19*L19+$B$20*L20) -> 1310.38 | ... W24: =W21-($B$2*W2+$B$3*W3+$B$4*W4+$B$5*W5+$B$6*W6+$B$7*W7+$B$8*W8+$B$9*W9+$B$10*W10+$B$11*W11+$B$12*W12+$B$13*W13+$B$14*W14+$B$15*W15+$B$16*W16+$B$17*W17+$B$18*W18+$B$19*W19+$B$20*W20) -> 0 | X24: =SUM(B24:W24) -> 21723.05
A25: Transport cost
A26: Net margin

Sheet Sheet6
A1: Customer name | B1: Inv No. | C1: Order details/ Prod Name | D1: MRP (in INR) | E1: Units | F1: Item Discount | G1: Total price/item (in INR)
A2: Kumar Saurav | B2: GAPL_0626_0001 | C2: Prod 1 | D2: Mrp | E2: unit | F2: Input Number | G2: 245
C3: Prod 2 | D3: Mrp | E3: unit | G3: 340
C4: Prod 3 | D4: Mrp | E4: unit
E6: Total Discount
D7: Total | E7: TotalItems | G7: TotalValue | H7: Publish PDF Invoice

Sheet Sheet1
A1: Product Name | B1: Landing Cost | C1: MRP | D1: Price/unit | E1: GST
A2: Mustard Oil - Organic | B2: ='June 26 Price List'!C2 -> 249.59 | C2: ='June 26 Price List'!D2 -> 440 | D2: ='June 26 Price List'!E2 -> 340 | E2: 0.05
A3: Mustard Oil - Regular | B3: ='June 26 Price List'!C3 -> 240.75 | C3: ='June 26 Price List'!D3 -> 310 | D3: ='June 26 Price List'!E3 -> 285 | E3: 0.05
A4: Groundnut Oil - Organic | B4: ='June 26 Price List'!C4 -> 257.99 | C4: ='June 26 Price List'!D4 -> 469 | D4: ='June 26 Price List'!E4 -> 350 | E4: 0.05
A5: Groundnut Oil - Regular | B5: ='June 26 Price List'!C5 -> 278.21 | C5: ='June 26 Price List'!D5 -> 339 | D5: ='June 26 Price List'!E5 -> 325 | E5: 0.05
A6: Sunflower Oil - Organic | B6: ='June 26 Price List'!C6 -> 262.79 | C6: ='June 26 Price List'!D6 -> 469 | D6: ='June 26 Price List'!E6 -> 350 | E6: 0.05
A7: Coconut Oil - Regular | B7: ='June 26 Price List'!C7 -> 60.99 | C7: ='June 26 Price List'!D7 -> 159 | D7: ='June 26 Price List'!E7 -> 109 | E7: 0.05
A8: Sesame Oil - Regular | B8: ='June 26 Price List'!C8 -> 42.8 | C8: ='June 26 Price List'!D8 -> 159 | D8: ='June 26 Price List'!E8 -> 109 | E8: 0.05
A9: A2 Ghee Gir Cow | B9: ='June 26 Price List'!C9 -> 1284.02 | C9: ='June 26 Price List'!D9 -> 2099 | D9: ='June 26 Price List'!E9 -> 1699 | E9: 0.05
A10: Chana Dal- Organic | B10: ='June 26 Price List'!C10 -> 96 | C10: ='June 26 Price List'!D10 -> 189 | D10: ='June 26 Price List'!E10 -> 150 | E10: 0
A11: Moong Dal - Organic | B11: ='June 26 Price List'!C11 -> 136.79 | C11: ='June 26 Price List'!D11 -> 219 | D11: ='June 26 Price List'!E11 -> 180 | E11: 0
A12: Tuar Dal - Organic | B12: ='June 26 Price List'!C12 -> 166.79 | C12: ='June 26 Price List'!D12 -> 239 | D12: ='June 26 Price List'!E12 -> 199 | E12: 0
A13: Masoor Dal- Organic | B13: ='June 26 Price List'!C13 -> 116.39 | C13: ='June 26 Price List'!D13 -> 219 | D13: ='June 26 Price List'!E13 -> 180 | E13: 0
... A20: Coconut Husk | B20: ='June 26 Price List'!C20 -> 31 | C20: ='June 26 Price List'!D20 -> 0 | D20: ='June 26 Price List'!E20 -> 0 | E20: 0
A21: Total
A22: Discount
A23: Discount %
A24: Margin
A25: Transport cost
A26: Net margin

Sheet June 26 Price List
A1: Product Name | B1: HSN | C1: Landing Cost | D1: MRP | E1: Selling Price | F1: Discount % | G1: D2C Transport Cost | H1: Margin | I1: Margin 2
A2: Mustard Oil - Organic | B2: ='Landed cost breakdown'!C13 -> 15149120 | C2: ='Landed cost breakdown'!J13 -> 249.59 | D2: ='Landed cost breakdown'!K13 -> 440 | E2: ='Landed cost breakdown'!L13 -> 340 | F2: =(D2-E2)/D2 -> 0.22727273 | H2: =E2-C2-G2 -> 90.41 | I2: =H2/E2 -> 0.26591176
A3: Mustard Oil - Regular | B3: ='Landed cost breakdown'!C5 -> 15149120 | C3: ='Landed cost breakdown'!J5 -> 240.75 | D3: ='Landed cost breakdown'!K5 -> 310 | E3: ='Landed cost breakdown'!L5 -> 285 | F3: =(D3-E3)/D3 -> 0.080645161 | H3: =E3-C3-G3 -> 44.25 | I3: =H3/E3 -> 0.15526316
A4: Groundnut Oil - Organic | B4: ='Landed cost breakdown'!C14 -> 15089010 | C4: ='Landed cost breakdown'!J14 -> 257.99 | D4: ='Landed cost breakdown'!K14 -> 469 | E4: ='Landed cost breakdown'!L14 -> 350 | F4: =(D4-E4)/D4 -> 0.25373134 | H4: =E4-C4-G4 -> 92.01 | I4: =H4/E4 -> 0.26288571
A5: Groundnut Oil - Regular | B5: ='Landed cost breakdown'!C6 -> 15081000 | C5: ='Landed cost breakdown'!J6 -> 278.21 | D5: ='Landed cost breakdown'!K6 -> 339 | E5: ='Landed cost breakdown'!L6 -> 325 | F5: =(D5-E5)/D5 -> 0.041297935 | H5: =E5-C5-G5 -> 46.79 | I5: =H5/E5 -> 0.14396923
A6: Sunflower Oil - Organic | B6: ='Landed cost breakdown'!C15 -> 15121910 | C6: ='Landed cost breakdown'!J15 -> 262.79 | D6: ='Landed cost breakdown'!K15 -> 469 | E6: ='Landed cost breakdown'!L15 -> 350 | F6: =(D6-E6)/D6 -> 0.25373134 | H6: =E6-C6-G6 -> 87.21 | I6: =H6/E6 -> 0.24917143
A7: Coconut Oil - Regular | B7: ='Landed cost breakdown'!C7 -> 15131100 | C7: ='Landed cost breakdown'!J7 -> 60.99 | D7: ='Landed cost breakdown'!K7 -> 159 | E7: ='Landed cost breakdown'!L7 -> 109 | F7: =(D7-E7)/D7 -> 0.31446541 | H7: =E7-C7-G7 -> 48.01 | I7: =H7/E7 -> 0.44045872
A8: Sesame Oil - Regular | B8: ='Landed cost breakdown'!C8 -> 15155099 | C8: ='Landed cost breakdown'!J8 -> 42.8 | D8: ='Landed cost breakdown'!K8 -> 159 | E8: ='Landed cost breakdown'!L8 -> 109 | F8: =(D8-E8)/D8 -> 0.31446541 | H8: =E8-C8-G8 -> 66.2 | I8: =H8/E8 -> 0.60733945
A9: A2 Ghee Gir Cow | B9: ='Landed cost breakdown'!C9 -> 4059020 | C9: ='Landed cost breakdown'!J9 -> 1284.02 | D9: ='Landed cost breakdown'!K9 -> 2099 | E9: ='Landed cost breakdown'!L9 -> 1699 | F9: =(D9-E9)/D9 -> 0.19056694 | H9: =E9-C9-G9 -> 414.98 | I9: =H9/E9 -> 0.24424956
A10: Chana Dal- Organic | B10: ='Landed cost breakdown'!C16 -> 7139010 | C10: ='Landed cost breakdown'!J16 -> 96 | D10: ='Landed cost breakdown'!K16 -> 189 | E10: ='Landed cost breakdown'!L16 -> 150 | F10: =(D10-E10)/D10 -> 0.20634921 | H10: =E10-C10-G10 -> 54 | I10: =H10/E10 -> 0.36
A11: Moong Dal - Organic | B11: ='Landed cost breakdown'!C19 -> 7133100 | C11: ='Landed cost breakdown'!J19 -> 136.79 | D11: ='Landed cost breakdown'!K19 -> 219 | E11: ='Landed cost breakdown'!L19 -> 180 | F11: =(D11-E11)/D11 -> 0.17808219 | H11: =E11-C11-G11 -> 43.21 | I11: =H11/E11 -> 0.24005556
A12: Tuar Dal - Organic | B12: ='Landed cost breakdown'!C17 -> 7136000 | C12: ='Landed cost breakdown'!J17 -> 166.79 | D12: ='Landed cost breakdown'!K17 -> 239 | E12: ='Landed cost breakdown'!L17 -> 199 | F12: =(D12-E12)/D12 -> 0.16736402 | H12: =E12-C12-G12 -> 32.21 | I12: =H12/E12 -> 0.1618593
A13: Masoor Dal- Organic | B13: ='Landed cost breakdown'!C18 -> 7134000 | C13: ='Landed cost breakdown'!J18 -> 116.39 | D13: ='Landed cost breakdown'!K18 -> 219 | E13: ='Landed cost breakdown'!L18 -> 180 | F13: =(D13-E13)/D13 -> 0.17808219 | H13: =E13-C13-G13 -> 63.61 | I13: =H13/E13 -> 0.35338889
A14: Basmati Rice- Organic | B14: ='Landed cost breakdown'!C21 -> 10063020 | C14: ='Landed cost breakdown'!J21 -> 143.99 | D14: ='Landed cost breakdown'!K21 -> 210 | E14: ='Landed cost breakdown'!L21 -> 210 | F14: =(D14-E14)/D14 -> 0 | H14: =E14-C14-G14 -> 66.01 | I14: =H14/E14 -> 0.31433333
A15: Sona Masoori Rice - Organic | B15: ='Landed cost breakdown'!C20 -> 10063010 | C15: ='Landed cost breakdown'!J20 -> 76.8 | D15: ='Landed cost breakdown'!K20 -> 139 | E15: ='Landed cost breakdown'!L20 -> 100 | F15: =(D15-E15)/D15 -> 0.28057554 | H15: =E15-C15-G15 -> 23.2 | I15: =H15/E15 -> 0.232
A16: JeeraPhool Rice - Organic | B16: ='Landed cost breakdown'!C23 -> — | C16: ='Landed cost breakdown'!J23 -> 88.23 | D16: ='Landed cost breakdown'!K23 -> 259 | E16: ='Landed cost breakdown'!L23 -> 240 | F16: =(D16-E16)/D16 -> 0.073359073 | H16: =E16-C16-G16 -> 151.77 | I16: =H16/E16 -> 0.632375
A17: Khapli Aata - Regular | B17: ='Landed cost breakdown'!C10 -> 1101 | C17: ='Landed cost breakdown'!J10 -> 101.65 | D17: ='Landed cost breakdown'!K10 -> 159 | E17: ='Landed cost breakdown'!L10 -> 149 | F17: =(D17-E17)/D17 -> 0.062893082 | H17: =E17-C17-G17 -> 47.35 | I17: =H17/E17 -> 0.31778523
A18: Whole Spices - Organic | B18: =_xludf.TEXTJOIN(CHAR(10), TRUE, 'Landed cost breakdown'!C26:C30) -> #NAME? | C18: 131.2 | D18: 299 | E18: 250 | F18: =(D18-E18)/D18 -> 0.1638796 | H18: =E18-C18-G18 -> 118.8 | I18: =H18/E18 -> 0.4752
A19: Ground Spices - Organic | B19: =_xludf.TEXTJOIN(CHAR(10), TRUE, 'Landed cost breakdown'!C33:C36) -> #NAME? | C19: 134.5 | D19: 299 | E19: 250 | F19: =(D19-E19)/D19 -> 0.1638796 | H19: =E19-C19-G19 -> 115.5 | I19: =H19/E19 -> 0.462
A20: Coconut Husk | B20: - | C20: 31 | D20: 0 | E20: 0 | F20: 1 | H20: =E20-C20-G20 -> -31 | I20: -1

Sheet Landed cost breakdown
A1: Purnavah — Landed Cost & Pricing Master (June 2026)
A2: Blue = hardcoded input | Black = formula | Freight apportioned by invoice value share | IGST excluded (recoverable ITC)
A3: Product | B3: Supplier | C3: HSN | D3: Unit | E3: Inv Rate (excl tax) | F3: Qty Purchased | G3: Invoice Value () | H3: Freight Allocated () | I3: Total Landed () | J3: Landed / Unit () | K3: MRP () | L3: Selling Price () | M3: Gross Margin % | O3: Freight Assumptions
A4: GRAMINN ORGANIK LINE | O4: Gavyadhar — invoice transport+packing
A5: Mustard Oil | B5: Graminn | C5: 15149120 | D5: 1 L | E5: 225 | F5: 70 | G5: 15750 | H5: 1102.82 | I5: 16852.82 | J5: 240.75 | K5: 310 | L5: 285 | M5: 0.155 | O5: Gavyadhar — additional Delhivery
A6: Groundnut Oil | B6: Graminn | C6: 15081000 | D6: 1 L | E6: 260 | F6: 30 | G6: 7800 | H6: 546.16 | I6: 8346.16 | J6: 278.21 | K6: 339 | L6: 325 | M6: 0.144 | O6: Gavyadhar total freight
A7: Coconut Oil | B7: Graminn | C7: 15131100 | D7: 100 ml | E7: 57 | F7: 100 | G7: 5700 | H7: 399.11 | I7: 6099.11 | J7: 60.99 | K7: 159 | L7: 109 | M7: 0.44 | O7: Gavyadhar invoice product total
A8: Sesame Oil | B8: Graminn | C8: 15155099 | D8: 100 ml | E8: 40 | F8: 100 | G8: 4000 | H8: 280.08 | I8: 4280.08 | J8: 42.8 | K8: 159 | L8: 109 | M8: 0.607 | O8: Graminn — VRL freight (6700+1900+100)
A9: A2 Bilona Ghee | B9: Graminn | C9: 4059020 | D9: 1 L | E9: 1200 | F9: 60 | G9: 72000 | H9: 5041.45 | I9: 77041.45 | J9: 1284.02 | K9: 2099 | L9: 1699 | M9: 0.244 | O9: Graminn invoice product total
A10: Khapli Flour | B10: Graminn | C10: 1101 | D10: 1 kg | E10: 95 | F10: 100 | G10: 9500 | H10: 665.19 | I10: 10165.19 | J10: 101.65 | K10: 159 | L10: 149 | M10: 0.318 | O10: Packaging total (incl GST 18% + ₹50 extra)
A11: Khapli Flour | B11: Graminn | C11: 1101 | D11: 2 kg | E11: 95 | F11: 100 | G11: 9500 | H11: 665.19 | I11: 10165.19 | J11: 101.65 | K11: 269 | L11: 249 | M11: 0.592
A12: GAVYADHAR ORGANIC LINE
A13: Mustard Oil | B13: Gavyadhar | C13: 15149120 | D13: 1 L | E13: 208 | F13: 50 | G13: 10400 | H13: 2079.37 | I13: 12479.37 | J13: 249.59 | K13: 440 | L13: 340 | M13: 0.266
A14: Groundnut Oil | B14: Gavyadhar | C14: 15089010 | D14: 1 L | E14: 215 | F14: 25 | G14: 5375 | H14: 1074.67 | I14: 6449.67 | J14: 257.99 | K14: 469 | L14: 350 | M14: 0.263
A15: Sunflower Oil | B15: Gavyadhar | C15: 15121910 | D15: 1 L | E15: 219 | F15: 25 | G15: 5475 | H15: 1094.67 | I15: 6569.67 | J15: 262.79 | K15: 469 | L15: 350 | M15: 0.249
A16: Chana Dal | B16: Gavyadhar | C16: 7139010 | D16: 1 kg | E16: 80 | F16: 40 | G16: 3200 | H16: 639.8 | I16: 3839.8 | J16: 96 | K16: 189 | L16: 150 | M16: 0.36
A17: Tuar Dal | B17: Gavyadhar | C17: 7136000 | D17: 1 kg | E17: 139 | F17: 50 | G17: 6950 | H17: 1389.58 | I17: 8339.58 | J17: 166.79 | K17: 239 | L17: 199 | M17: 0.162
A18: Masoor Dal | B18: Gavyadhar | C18: 7134000 | D18: 1 kg | E18: 97 | F18: 40 | G18: 3880 | H18: 775.76 | I18: 4655.76 | J18: 116.39 | K18: 219 | L18: 180 | M18: 0.353
A19: Moong Dal | B19: Gavyadhar | C19: 7133100 | D19: 1 kg | E19: 114 | F19: 40 | G19: 4560 | H19: 911.72 | I19: 5471.72 | J19: 136.79 | K19: 219 | L19: 180 | M19: 0.24
A20: Sona Masoori Rice | B20: Gavyadhar | C20: 10063010 | D20: 1 kg | E20: 64 | F20: 60 | G20: 3840 | H20: 767.77 | I20: 4607.77 | J20: 76.8 | K20: 139 | L20: 100 | M20: 0.232
A21: Basmati Rice | B21: Gavyadhar | C21: 10063020 | D21: 1 kg | E21: 120 | F21: 10 | G21: 1200 | H21: 239.93 | I21: 1439.93 | J21: 143.99 | K21: 210 | L21: 210 | M21: 0.314
A22: OWN PRODUCE — GAPL FARM
A23: JeeraPhool Rice | B23: GAPL Farm | C23: — | D23: 1 kg | E23: 88.23 | F23: 1 | G23: 88.23 | H23: 0 | I23: 88.23 | J23: 88.23 | K23: 259 | L23: 240 | M23: 0.632
A24: VishnuBhog Rice | B24: GAPL/Procure | C24: — | D24: 1 kg | E24: TBD | F24: 1 | G24: TBD | H24: — | I24: TBD | J24: TBD | K24: 259 | L24: 259 | M24: TBD
A25: WHOLE SPICE BUNDLE (Gavyadhar)
A26: Jeera Seed | B26: Gavyadhar | C26: 9093111 | D26: 0.5 kg | E26: 310 | F26: 1 | G26: 155 | H26: 30.99 | I26: 185.99 | J26: 371.98 | K26: — | L26: — | M26: —
A27: Rai/Mustard Seed | B27: Gavyadhar | C27: 12075010 | D27: 0.5 kg | E27: 120 | F27: 1 | G27: 60 | H27: 12 | I27: 72 | J27: 143.99 | K27: — | L27: — | M27: —
A28: Methi Seed | B28: Gavyadhar | C28: 9109919 | D28: 0.5 kg | E28: 96 | F28: 1 | G28: 48 | H28: 9.6 | I28: 57.6 | J28: 115.19 | K28: — | L28: — | M28: —
A29: Coriander Whole | B29: Gavyadhar | C29: 9092110 | D29: 0.5 kg | E29: 192 | F29: 1 | G29: 96 | H29: 19.19 | I29: 115.19 | J29: 230.39 | K29: — | L29: — | M29: —
A30: Kali Mirch | B30: Gavyadhar | C30: 9041130 | D30: 0.5 kg | E30: 910 | F30: 1 | G30: 455 | H30: 90.97 | I30: 545.97 | J30: 1091.94 | K30: — | L30: — | M30: —
A31: Whole Bundle MRP / Sell | B31: Gavyadhar | C31: — | D31: bundle | E31: TBD | G31: TBD | H31: — | I31: TBD | J31: TBD | K31: 299 | L31: 250 | M31: —
A32: GROUND SPICE BUNDLE (Gavyadhar)
A33: Red Chilly Powder | B33: Gavyadhar | C33: 9042211 | D33: 3 kg | E33: 345 | F33: 3 | G33: 1035 | H33: 206.94 | I33: 1241.94 | J33: 413.98 | K33: — | L33: — | M33: —
A34: Haldi Powder | B34: Gavyadhar | C34: 9103030 | D34: 3 kg | E34: 228 | F34: 3 | G34: 684 | H34: 136.76 | I34: 820.76 | J34: 273.59 | K34: — | L34: — | M34: —
A35: Coriander Powder | B35: Gavyadhar | C35: 9092200 | D35: 3 kg | E35: 197 | F35: 3 | G35: 591 | H35: 118.16 | I35: 709.16 | J35: 236.39 | K35: — | L35: — | M35: —
A36: Jeera Powder | B36: Gavyadhar | C36: 9093111 | D36: 3 kg | E36: 325 | F36: 3 | G36: 975 | H36: 194.94 | I36: 1169.94 | J36: 389.98 | K36: — | L36: — | M36: —
A37: Ground Bundle MRP / Sell | B37: Gavyadhar | C37: — | D37: bundle | E37: TBD | G37: TBD | H37: — | I37: TBD | J37: TBD | K37: 299 | L37: 250 | M37: —
A38: PACKAGING MATERIAL (Vijay)
A39: Poly Bag 3.5×6 | B39: Vijay Pkg | C39: 39232990 | D39: 1000 pcs | E39: 1.75 | F39: 1000 | G39: 1750 | H39: 0 | I39: 1750 | J39: 1.75 | K39: — | L39: — | M39: —
A40: Poly Bag 5×8 | B40: Vijay Pkg | C40: 39232990 | D40: 1000 pcs | E40: 3 | F40: 1000 | G40: 3000 | H40: 0 | I40: 3000 | J40: 3 | K40: — | L40: — | M40: —
...
